console.log("Log 1");

setTimeout(() => console.log("Async log"), 1000);

console.log("Log 2");
console.log("Log 3");


// função que gera um número aleatório
const generateRandomNumber = () => Math.round(Math.random() * 10);

// promise resolvida retornando o número aleatório
// const resolvedPromise = () =>
//   new Promise((resolve, reject) => {
//     setTimeout(() => {
//       const randomNumber = generateRandomNumber();
//       resolve(randomNumber);
//     }, 1000);
//   });

// promise rejeitada retornando um objeto de erro
const rejectedPromise = () =>
  new Promise((resolve, reject) => {
    setTimeout(() => {
      const randomNumber = generateRandomNumber();
      reject(new Error(`O número ${randomNumber} é inválido.`));
    }, 1000);
  });